Workbook
Name ANNEE: #REF!
Name Budget: [1]Budget!$B$5:$O$28
Name Budget: #REF!
Name BudgetCum: [1]Budget!$B$31:$O$54
Name BudgetCum: #REF!
Name CA: [2]TDB!$B$4:$O$15
Name CA: [2]TDB!$B$4:$O$15
Name CA: [2]TDB!$B$4:$O$15
Name CA: [2]TDB!$B$4:$O$15
Name CA: [2]TDB!$B$4:$O$15
Name CA: [3]TDB!$B$4:$O$15
Name cge: #REF!
Name cge: #REF!
Name CH: [2]TDB!$A$20:$O$42
Name CH: [2]TDB!$A$20:$O$42
Name CH: [2]TDB!$A$20:$O$42
Name CH: [2]TDB!$A$20:$O$42
Name CH: [2]TDB!$A$20:$O$42
Name CH: [3]TDB!$A$20:$O$42
Name data1: '[4]Cal. 1'!$AQ$4:$AQ$23
Name data1: '[5]Cal. 1'!$AQ$4:$AQ$23
Name data1: '[4]Cal. 1'!$AQ$4:$AQ$23
Name data1: '[4]Cal. 1'!$AQ$4:$AQ$23
Name data1: '[4]Cal. 1'!$AQ$4:$AQ$23
Name data1: '[4]Cal. 1'!$AQ$4:$AQ$23
Name data1: '[5]Cal. 1'!$AQ$4:$AQ$23
Name data2: '[4]Cal. 1'!$AT$4:$AT$23
Name data2: '[5]Cal. 1'!$AT$4:$AT$23
Name data2: '[4]Cal. 1'!$AT$4:$AT$23
Name data2: '[4]Cal. 1'!$AT$4:$AT$23
Name data2: '[4]Cal. 1'!$AT$4:$AT$23
Name data2: '[4]Cal. 1'!$AT$4:$AT$23
Name data2: '[5]Cal. 1'!$AT$4:$AT$23
Name Entrée: #REF!
Name f: #REF!
Name f: #REF!
Name Feries: [4]BDD!$A$2:$A$18
Name Feries: [5]BDD!$A$2:$A$18
Name Feries: [4]BDD!$A$2:$A$18
Name Feries: [4]BDD!$A$2:$A$18
Name Feries: [4]BDD!$A$2:$A$18
Name Feries: [4]BDD!$A$2:$A$18
Name Feries: [5]BDD!$A$2:$A$18
Name Fournisseur: #REF!+#REF!
Name Frais: [6]Annexe!$A$4:$A$21
Name nom: #REF!
Name nom: #REF!
Name Obj: '[1]CA Objectif'!$B$3:$O$13
Name Obj: #REF!
Name OCA: '[2]TDB prev'!$B$2:$O$13
Name OCA: '[2]TDB prev'!$B$2:$O$13
Name OCA: '[2]TDB prev'!$B$2:$O$13
Name OCA: '[2]TDB prev'!$B$2:$O$13
Name OCA: '[2]TDB prev'!$B$2:$O$13
Name OCA: '[3]TDB prev'!$B$2:$O$13
Name OCH: '[2]TDB prev'!$B$16:$O$38
Name OCH: '[2]TDB prev'!$B$16:$O$38
Name OCH: '[2]TDB prev'!$B$16:$O$38
Name OCH: '[2]TDB prev'!$B$16:$O$38
Name OCH: '[2]TDB prev'!$B$16:$O$38

Sheet Données
A1: الشركة | B1: صياغة الفتح
A2: السنة التجارية | B2: 2023-2024
A4: تاريخ بداية السنة التجارية | B4: 45142
A6: تاريخ نهاية السنة التجارية | B6: 45583
A8: عدد أيام السنة التجارية | B8: =B6-B4 -> 441
A10: نسبة الزكاة | B10: =ROUNDUP((B8*2.5%)/355,4) -> 0.0311
A12: المكلف بالتصفية: | B12: الواهج عمر
A13: المستلم منه المعلومات: | B13: الواهج عمر
A14: يوم تسليم الميزانية:

Sheet Nv capital
A1: ="حساب رؤوس الأموال الجديدة لسنة "&Données!B2 -> حساب رؤوس الأموال الجديدة لسنة 2023-2024
E3: رأس المال الافتتاحي | F3: مخارج رأس المال | G3: مداخيل رأس المال | H3: رأس المال 2016-2017
D4: صياغة الفتح | E4: =C9-D9 -> 33804739 | F4: =G5+G6 -> 13114674 | G4: =+E9 -> 3100310 | H4: =E4-F4+G4 -> 23790375
D5: الورشة B2 | G5: =8665344.67+1115281 -> 9780625.7 | H5: =E5-F5+G5 -> 9780625.7
D6: الورشة B1 | G6: =3052625+281423.22 -> 3334048.2 | H6: =E6-F6+G6 -> 3334048.2
D7: المجموع | E7: =SUM(E4:E6) -> 33804739 | F7: =SUM(F4:F6) -> 13114674 | G7: =SUM(G4:G6) -> 16214984 | H7: =SUM(H4:H6) -> 36905049
C9: =SUBTOTAL(9,C11:C82) -> 33804739 | D9: =SUBTOTAL(9,D11:D1799) -> 0 | E9: =SUBTOTAL(9,E11:E82) -> 3100310 | H9: =SUBTOTAL(9,H11:H1799) -> 36905049 | I9: =SUBTOTAL(9,I11:I1799) -> 35626133
A10: الرقم | B10: الشركاء | C10: رؤوس الأموال نهاية 2024-2023 | D10: ="سحوبات "&Données!$B$2 -> سحوبات 2023-2024 | E10: ="مداخيل "&Données!$B$2 -> مداخيل 2023-2024 | F10: التاريخ | G10: عدد أيام العمل | H10: ="رؤوس الأموال "&Données!$B$2 -> رؤوس الأموال 2023-2024 | I10: رأس المال النسبي
A11: 1 | B11: الواهج عمر بن يحي | G11: =IF(F11="",Données!$B$6-Données!$B$4,Données!$B$6-F11) -> 441 | H11: =C11-D11+E11 -> 0 | I11: =C11-D11+E11*(G11/Données!$B$8) -> 0
A12: 2 | B12: بن عزوز مبخوتة | C12: 10000000 | G12: =IF(F12="",Données!$B$6-Données!$B$4,Données!$B$6-F12) -> 441 | H12: =C12-D12+E12 -> 10000000 | I12: =C12-D12+E12*(G12/Données!$B$8) -> 10000000
A13: 3 | B13: كروشي الحاج بابهون | C13: =10405921.17-238000 -> 10167921 | G13: =IF(F13="",Données!$B$6-Données!$B$4,Données!$B$6-F13) -> 441 | H13: =C13-D13+E13 -> 10167921 | I13: =C13-D13+E13*(G13/Données!$B$8) -> 10167921
A14: 4 | B14: بوسربة ياسمينة | C14: 607993.9 | G14: =IF(F14="",Données!$B$6-Données!$B$4,Données!$B$6-F14) -> 441 | H14: =C14-D14+E14 -> 607993.9 | I14: =C14-D14+E14*(G14/Données!$B$8) -> 607993.9
A15: 5 | B15: بعوشي رسثم | C15: 1000000 | G15: =IF(F15="",Données!$B$6-Données!$B$4,Données!$B$6-F15) -> 441 | H15: =C15-D15+E15 -> 1000000 | I15: =C15-D15+E15*(G15/Données!$B$8) -> 1000000
A16: 6 | B16: بوسريح نعيمة | C16: 500000 | G16: =IF(F16="",Données!$B$6-Données!$B$4,Données!$B$6-F16) -> 441 | H16: =C16-D16+E16 -> 500000 | I16: =C16-D16+E16*(G16/Données!$B$8) -> 500000
A17: 7 | B17: بكاير حرمية بنت محمد | C17: 719297.09 | G17: =IF(F17="",Données!$B$6-Données!$B$4,Données!$B$6-F17) -> 441 | H17: =C17-D17+E17 -> 719297.09 | I17: =C17-D17+E17*(G17/Données!$B$8) -> 719297.09
A18: 8 | B18: بكاير رابح بن محمد | C18: =2508503.53-325000 -> 2183503.5 | G18: =IF(F18="",Données!$B$6-Données!$B$4,Données!$B$6-F18) -> 441 | H18: =C18-D18+E18 -> 2183503.5 | I18: =C18-D18+E18*(G18/Données!$B$8) -> 2183503.5
A19: 9 | B19: لعساكر عبد الحميد | C19: =1406263.99-31000 -> 1375264 | G19: =IF(F19="",Données!$B$6-Données!$B$4,Données!$B$6-F19) -> 441 | H19: =C19-D19+E19 -> 1375264 | I19: =C19-D19+E19*(G19/Données!$B$8) -> 1375264
A20: 10 | B20: الواهج احمد | C20: 708995.97 | G20: =IF(F20="",Données!$B$6-Données!$B$4,Données!$B$6-F20) -> 441 | H20: =C20-D20+E20 -> 708995.97 | I20: =C20-D20+E20*(G20/Données!$B$8) -> 708995.97
A21: 11 | B21: مبروك مبروك طولقة | C21: 3000000 | G21: =IF(F21="",Données!$B$6-Données!$B$4,Données!$B$6-F21) -> 441 | H21: =C21-D21+E21 -> 3000000 | I21: =C21-D21+E21*(G21/Données!$B$8) -> 3000000
A22: 12 | B22: بن يامي فؤاد بن علي | C22: 340739.85 | G22: =IF(F22="",Données!$B$6-Données!$B$4,Données!$B$6-F22) -> 441 | H22: =C22-D22+E22 -> 340739.85 | I22: =C22-D22+E22*(G22/Données!$B$8) -> 340739.85
A23: 13 | B23: الواهج اسية | C23: 513448.84 | G23: =IF(F23="",Données!$B$6-Données!$B$4,Données!$B$6-F23) -> 441 | H23: =C23-D23+E23 -> 513448.84 | I23: =C23-D23+E23*(G23/Données!$B$8) -> 513448.84
A24: 14 | B24: صالح والحاج خوخة | C24: =22019.02+50104.05 -> 72123.07 | G24: =IF(F24="",Données!$B$6-Données!$B$4,Données!$B$6-F24) -> 441 | H24: =C24-D24+E24 -> 72123.07 | I24: =C24-D24+E24*(G24/Données!$B$8) -> 72123.07
A25: 15 | B25: الواهج مامة | E25: 500000 | F25: 45376 | G25: =IF(F25="",Données!$B$6-Données!$B$4,Données!$B$6-F25) -> 207 | H25: =C25-D25+E25 -> 500000 | I25: =C25-D25+E25*(G25/Données!$B$8) -> 234693.88
A26: 16 | B26: صالح والحاج فاطمة | C26: 22034.67 | G26: =IF(F26="",Données!$B$6-Données!$B$4,Données!$B$6-F26) -> 441 | H26: =C26-D26+E26 -> 22034.67 | I26: =C26-D26+E26*(G26/Données!$B$8) -> 22034.67
A27: 17 | B27: موسى المال سليمان | C27: 642035.45 | G27: =IF(F27="",Données!$B$6-Données!$B$4,Données!$B$6-F27) -> 441 | H27: =C27-D27+E27 -> 642035.45 | I27: =C27-D27+E27*(G27/Données!$B$8) -> 642035.45
A28: 18 | B28: باسليمان محمد بن صالح | C28: 403492.59 | G28: =IF(F28="",Données!$B$6-Données!$B$4,Données!$B$6-F28) -> 441 | H28: =C28-D28+E28 -> 403492.59 | I28: =C28-D28+E28*(G28/Données!$B$8) -> 403492.59
A29: 19 | B29: بن يامي اسلام بن حمزة | E29: 70000 | F29: 45238 | G29: =IF(F29="",Données!$B$6-Données!$B$4,Données!$B$6-F29) -> 345 | H29: =C29-D29+E29 -> 70000 | I29: =C29-D29+E29*(G29/Données!$B$8) -> 54761.905
A30: 20 | B30: بن يامي محمد بن حمزة | E30: 100000 | F30: 45238 | G30: =IF(F30="",Données!$B$6-Données!$B$4,Données!$B$6-F30) -> 345 | H30: =C30-D30+E30 -> 100000 | I30: =C30-D30+E30*(G30/Données!$B$8) -> 78231.293
A31: 21 | B31: خن لقمان | E31: 110310 | F31: 45342 | G31: =IF(F31="",Données!$B$6-Données!$B$4,Données!$B$6-F31) -> 241 | H31: =C31-D31+E31 -> 110310 | I31: =C31-D31+E31*(G31/Données!$B$8) -> 60282.789
A32: 22 | B32: مدرسة فسايل الامل | E32: 1200000 | F32: 45242 | G32: =IF(F32="",Données!$B$6-Données!$B$4,Données!$B$6-F32) -> 341 | H32: =C32-D32+E32 -> 1200000 | I32: =C32-D32+E32*(G32/Données!$B$8) -> 927891.16
A33: 23 | B33: الواهج فاطمة الزهراء | E33: 100000 | F33: 45558 | G33: =IF(F33="",Données!$B$6-Données!$B$4,Données!$B$6-F33) -> 25 | H33: =C33-D33+E33 -> 100000 | I33: =C33-D33+E33*(G33/Données!$B$8) -> 5668.9342
A34: 24 | B34: الواهج لالة | E34: 180000 | F34: 45351 | G34: =IF(F34="",Données!$B$6-Données!$B$4,Données!$B$6-F34) -> 232 | H34: =C34-D34+E34 -> 180000 | I34: =C34-D34+E34*(G34/Données!$B$8) -> 94693.878
A35: 25 | B35: صالح والحاج ادريس بن سليمان | E35: 100000 | F35: 45487 | G35: =IF(F35="",Données!$B$6-Données!$B$4,Données!$B$6-F35) -> 96 | H35: =C35-D35+E35 -> 100000 | I35: =C35-D35+E35*(G35/Données!$B$8) -> 21768.707
A36: 26 | B36: صالح والحاج سليمان بن عمر | E36: 100000 | F36: 45185 | G36: =IF(F36="",Données!$B$6-Données!$B$4,Données!$B$6-F36) -> 398 | H36: =C36-D36+E36 -> 100000 | I36: =C36-D36+E36*(G36/Données!$B$8) -> 90249.433
A37: 27 | B37: صالح والحاج سليمان ين عمر | E37: 500000 | F37: 45444 | G37: =IF(F37="",Données!$B$6-Données!$B$4,Données!$B$6-F37) -> 139 | H37: =C37-D37+E37 -> 500000 | I37: =C37-D37+E37*(G37/Données!$B$8) -> 157596.37
A38: 28 | B38: طالب باحمد نانة | E38: 40000 | F38: 45342 | G38: =IF(F38="",Données!$B$6-Données!$B$4,Données!$B$6-F38) -> 241 | H38: =C38-D38+E38 -> 40000 | I38: =C38-D38+E38*(G38/Données!$B$8) -> 21859.41
A39: 29 | B39: النادي الرياضي فسائل الامل | E39: 100000 | F39: 45258 | G39: =IF(F39="",Données!$B$6-Données!$B$4,Données!$B$6-F39) -> 325 | H39: =C39-D39+E39 -> 100000 | I39: =C39-D39+E39*(G39/Données!$B$8) -> 73696.145
A40: 30 | B40: الواهج عمر بن يحي بن حمو | C40: 1547888.9 | G40: =IF(F40="",Données!$B$6-Données!$B$4,Données!$B$6-F40) -> 441 | H40: =C40-D40+E40 -> 1547888.9 | I40: =C40-D40+E40*(G40/Données!$B$8) -> 1547888.9 | J40: امانة من سنة 2022 ليست في ذمتي 1547888.92

Sheet  Bilan cloture
A1: ="ميزانية مؤسسة "&Données!B1&" في "&DAY(Données!$B$6)&"/"&MONTH(Données!$B$6)&"/"&YEAR(Données!$B$6) -> ميزانية مؤسسة صياغة الفتح في 18/10/2024
A3: Actif / الأصول | F3: Passif / الخصوم
A4: Code | B4: Libéllé de l'Opération | D4: Montant | F4: Code | G4: Libéllé de l'Opération | I4: Montant
A5: Compta | F5: Compta
A6: =D6/D29 -> 0.051069103 | B6: Investissement / الاستثمارات | D6: =SUM(D7:D10) -> 4085540 | F6: =I6/I29 -> 0.29737883 | G6: Fonds Propres / رؤوس الأموال | I6: =SUM(I7:I10) -> 23790375
A7: 2 | B7: Materiels & équipements | C7: التجهيزات | D7: ='Invest Mag'!D8 -> 569310 | F7: 1 | G7: Capiteaux des associés | H7: رؤوس أموال الشركاء | I7: ='Nv capital'!H4 -> 23790375
B8: Matériel Roulant | C8: معدات النقل | D8: 2000000
B9: Materiels & équipements | C9: التجهيزات | D9: ='invest AtB3'!E2 -> 1516230
B10: Materiels & équipements | C10: التجهيزات
A11: =D11/D29 -> 0.49605194 | B11: Stocks / المخزونات | D11: =SUM(D12:D14) -> 39684270 | F11: =I11/I29 -> 0.45281919 | G11: Dettes / الديون | I11: =SUM(I12:I19) -> 36225640
A12: 3 | B12: Stocks Marchandises OR | C12: مخزون السلع | D12: ='stocks or'!I1 -> 36489863 | F12: 4 | G12: Dettes Fournisseurs | H12: ديون الموردين | I12: =Frs!J2 -> 2441869.1
B13: Stocks Marchandises AGR | D13: ='stoks arg'!G1 -> 3044406.9
B14: Stocks Marchandises P/O | D14: ='stok PO'!G1 -> 150000 | G14: Dettes Fournisseurs Casse | H14: ديون الموردين | I14: =Frs!G2 -> 11721510
A15: =D15/D29 -> 0.43948696 | B15: Créances / الحقوق | D15: =SUM(D16:D24) -> 35159059 | G15: Avances clients (versements) | H15: تسبيقات الزبائن | I15: =client!J1 -> 16543749
A16: 4 | B16: Créances Clients | C16: مستحقات لدى الزبائن | D16: =client!I1 -> 5829108 | G16: Avances clients Casse | H16: تسبيقات الزبائن | I16: =client!G1 -> 5106570
B17: Créances Clients Casse | C17: مستحقات لدى الزبائن | D17: =client!F1 -> 9715 | G17: Dettes Personnel | I17: =personnel!I4 -> 411941.5
B18: Avances fournisseurs | C18: تسبيقات للموردين | D18: =Frs!I2 -> 267528.62 | G18: Dettes Inpot Tripinal Berriane
B19: Avances fournisseurs Casse 18 | C19: تسبيقات للموردين | D19: =Frs!F2 -> 1271360
B20: Avances fournisseurs Casse 21 | C20: تسبيقات للموردين | D20: =Frs!E4 -> 964260
B21: Avances associers | C21: تسبيقات للشركاء | D21: ='Avances asso'!C4 -> 20808199 | F21: 1 | G21: Résultat avant déduction des primes | I21: =D6+D11+D15+D25-I6-I11 -> 19984216
B22: Prêt salariés | C22: سلف للعمال | D22: =personnel!H4 -> 43869 | G22: Prime des salaries | H22: منح الموظفين
B23: at b1 | C23: الفائدة | D23: 2630971.2 | G23: ELMACHRI3 ELKHIRIA | H23: المشاريع الخيرية
B24: at b2 | C24: الفائدة | D24: 3334048.2 | G24: Résultat net de l'exercice / النتيجة الصافية للدورة | I24: =I21-SUM(I22:I23) -> 19984216
A25: =D25/D29 -> 0.01339199 | B25: Disponibilités / السيولة | D25: =SUM(D26:D28) -> 1071362.3 | G25: Rentabilité du projet | H25: مردودية المشروع | I25: =I24/I6 -> 0.84001266
A26: 5 | B26: Trésorie | C26: الخزينة | D26: =170000+450000+155910 -> 775910
B27: Compte courant Banque BDL | C27: الحساب الجاري البنكي | D27: =4506.21+10946.07 -> 15452.28
B28: Devise-euro | C28: =370+300+450 -> 1120 | D28: =C28*250 -> 280000
B29: Total Actif | D29: =D6+D11+D15+D25 -> 80000231 | F29: Total Passif | I29: =I11+I6+I21 -> 80000231
B30: 111

Sheet Repartition globale
B6: رأس مال الشركة | D6: =' Bilan cloture'!I6 -> 23790375 | G6: B2 | H6: B1 | I6: المجموع
B7: النتيجة الدورة الصافية | D7: =' Bilan cloture'!I24 -> 19984216 | F7: رأس مال الشركة | G7: ='Nv capital'!H5 -> 9780625.7 | H7: ='Nv capital'!H6 -> 3334048.2 | I7: =D6+G7+H7 -> 36905049 | L7: =F11/D11 -> 0.43452994
B8: نصيب الشركاء بالجهد | C8: 0.5 | D8: =D$7*$C$8 -> 9992108.1 | F8: نصيب الشركاء بالمال | G8: ='[7]Repartition globale'!$E$13 -> 517342.62 | H8: ='[8]Repartition globale'!$D$8 -> 498830.08 | I8: =D9+G8+H8 -> 11008281
B9: نصيب الشركاء بالمال | C9: =100%-C8 -> 0.5 | D9: =D$7*$C$9 -> 9992108.1
A11: المجموع | C11: =SUM(C13:C61) -> 36905049 | D11: =SUM(D13:D19) -> 22995212 | E11: =SUM(E13:E19) -> 1 | F11: =SUM(F13:F19) -> 9992108.1 | G11: =SUM(G13:G19) -> 1 | H11: =SUM(H13:H19) -> 9992108.1 | I11: =SUM(I13:I19) -> 20088199 | J11: =SUM(J13:J19) -> 22891230 | K11: =SUM(K13:K19) -> 740505.93 | ... M11: =SUM(M13:M19) -> 1
A12: رقم | B12: الشركاء | C12: رأس المال الافتتاحي | D12: رأس المال النسبي | E12: نسب تقسيم رؤوس الأموال | F12: الأرباح مقابل المال | G12: نسب تقسيم أرباح الجهد | H12: الأرباح مقابل الجهد | I12: مقدم أرباح الشركاء | J12: المجموع | K12: زكاة السنة التجارية 2,58% | L12: رأس المال الجديد | M12: نسب رؤوس الأموال
A13: 1 | B13: ='Nv capital'!B11 -> الواهج عمر بن يحي | C13: ='Nv capital'!H11 -> 0 | D13: ='Nv capital'!I11 -> 0 | E13: =D13/$D$11 -> 0 | F13: =$D$9*E13 -> 0 | G13: 1 | H13: =$D$8*G13 -> 9992108.1 | I13: ='Avances asso'!C6 -> 19888199 | J13: =C13+F13+H13-I13 -> -9896090.5 | M13: =L13/$L$11 -> 0
A14: 2 | B14: ='Nv capital'!B12 -> بن عزوز مبخوتة | C14: ='Nv capital'!H12 -> 10000000 | D14: ='Nv capital'!I12 -> 10000000 | E14: =D14/$D$11 -> 0.43487313 | F14: =$D$9*E14 -> 4345299.4 | G14: 0 | H14: =$D$8*G14 -> 0 | I14: ='Avances asso'!C9 -> 0 | J14: =C14+F14+H14-I14 -> 14345299 | K14: =($J14-($E14*' Bilan cloture'!$D$6))*2.58% -> 324270.08 | L14: =J14 -> 14345299 | M14: =L14/$L$11 -> 0.43752583
A15: 3 | B15: ='Nv capital'!B13 -> كروشي الحاج بابهون | C15: ='Nv capital'!H13 -> 10167921 | D15: ='Nv capital'!I13 -> 10167921 | E15: =D15/$D$11 -> 0.44217558 | F15: =$D$9*E15 -> 4418266.2 | G15: 0 | H15: =$D$8*G15 -> 0 | I15: ='Avances asso'!C8 -> 0 | J15: =C15+F15+H15-I15 -> 14586187 | K15: =($J15-($E15*' Bilan cloture'!$D$6))*2.58% -> 329715.26 | L15: =J15 -> 14586187 | M15: =L15/$L$11 -> 0.44487281
A16: 4 | B16: ='Nv capital'!B14 -> بوسربة ياسمينة | C16: ='Nv capital'!H14 -> 607993.9 | D16: ='Nv capital'!I14 -> 607993.9 | E16: =D16/$D$11 -> 0.026440021 | F16: =$D$9*E16 -> 264191.55 | G16: 0 | H16: =$D$8*G16 -> 0 | I16: ='Avances asso'!C9 -> 0 | J16: =C16+F16+H16-I16 -> 872185.45 | K16: =($J16-($E16*' Bilan cloture'!$D$6))*2.58% -> 19715.423 | L16: =J16 -> 872185.45 | M16: =L16/$L$11 -> 0.026601303
A17: 5 | B17: ='Nv capital'!B15 -> بعوشي رسثم | C17: ='Nv capital'!C15 -> 1000000 | D17: ='Nv capital'!I15 -> 1000000 | E17: =D17/$D$11 -> 0.043487313 | F17: =$D$9*E17 -> 434529.94 | G17: 0 | H17: =$D$8*G17 -> 0 | I17: ='Avances asso'!C10 -> 200000 | J17: =C17+F17+H17-I17 -> 1234529.9 | K17: =($J17-($E17*' Bilan cloture'!$D$6))*2.58% -> 27267.008 | L17: =J17 -> 1234529.9 | M17: =L17/$L$11 -> 0.037652664
A18: 6 | B18: ='Nv capital'!B16 -> بوسريح نعيمة | C18: ='Nv capital'!C16 -> 500000 | D18: ='Nv capital'!I16 -> 500000 | E18: =D18/$D$11 -> 0.021743657 | F18: =$D$9*E18 -> 217264.97 | G18: 0 | H18: =$D$8*G18 -> 0 | I18: ='Avances asso'!C11 -> 0 | J18: =C18+F18+H18-I18 -> 717264.97 | K18: =($J18-($E18*' Bilan cloture'!$D$6))*2.58% -> 16213.504 | L18: =J18 -> 717264.97 | M18: =L18/$L$11 -> 0.021876291
A19: 7 | B19: ='Nv capital'!B17 -> بكاير حرمية بنت محمد | C19: ='Nv capital'!C17 -> 719297.09 | D19: ='Nv capital'!I17 -> 719297.09 | E19: =D19/$D$11 -> 0.031280298 | F19: =$D$9*E19 -> 312556.12 | G19: 0 | H19: =$D$8*G19 -> 0 | I19: ='Avances asso'!C12 -> 0 | J19: =C19+F19+H19-I19 -> 1031853.2 | K19: =($J19-($E19*' Bilan cloture'!$D$6))*2.58% -> 23324.653 | L19: =J19 -> 1031853.2 | M19: =L19/$L$11 -> 0.031471105
A20: 8 | B20: بكاير رابح بن محمد | C20: ='Nv capital'!C18 -> 2183503.5 | D20: ='Nv capital'!I18 -> 2183503.5 | E20: =D20/$D$11 -> 0.094954703 | F20: =$D$9*E20 -> 948797.65 | G20: 0 | H20: =$D$8*G20 -> 0 | I20: ='Avances asso'!C13 -> 0 | J20: =C20+F20+H20-I20 -> 3132301.2 | K20: =($J20-($E20*' Bilan cloture'!$D$6))*2.58% -> 70804.487 | L20: =J20 -> 3132301.2 | M20: =L20/$L$11 -> 0.095533919
A21: 9 | B21: ='Nv capital'!B19 -> لعساكر عبد الحميد | C21: ='Nv capital'!C19 -> 1375264 | D21: ='Nv capital'!I19 -> 1375264 | E21: =D21/$D$11 -> 0.059806536 | F21: =$D$9*E21 -> 597593.38 | G21: 0 | H21: =$D$8*G21 -> 0 | I21: ='Avances asso'!C14 -> 70000 | J21: =C21+F21+H21-I21 -> 1902857.4 | K21: =($J21-($E21*' Bilan cloture'!$D$6))*2.58% -> 42789.697 | L21: =J21 -> 1902857.4 | M21: =L21/$L$11 -> 0.05803638
A22: 10 | B22: ='Nv capital'!B20 -> الواهج احمد | C22: ='Nv capital'!C20 -> 708995.97 | D22: ='Nv capital'!I20 -> 708995.97 | E22: =D22/$D$11 -> 0.03083233 | F22: =$D$9*E22 -> 308079.98 | G22: 0 | H22: =$D$8*G22 -> 0 | I22: ='Avances asso'!C15 -> 0 | J22: =C22+F22+H22-I22 -> 1017075.9 | K22: =($J22-($E22*' Bilan cloture'!$D$6))*2.58% -> 22990.618 | L22: =J22 -> 1017075.9 | M22: =L22/$L$11 -> 0.031020405
A23: 11 | B23: ='Nv capital'!B21 -> مبروك مبروك طولقة | C23: ='Nv capital'!C21 -> 3000000 | D23: ='Nv capital'!I21 -> 3000000 | E23: =D23/$D$11 -> 0.13046194 | F23: =$D$9*E23 -> 1303589.8 | G23: 0 | H23: =$D$8*G23 -> 0 | I23: ='Avances asso'!C16 -> 0 | J23: =C23+F23+H23-I23 -> 4303589.8 | K23: =($J23-($E23*' Bilan cloture'!$D$6))*2.58% -> 97281.024 | L23: =J23 -> 4303589.8 | M23: =L23/$L$11 -> 0.13125775
A24: 12 | B24: ='Nv capital'!B22 -> بن يامي فؤاد بن علي | C24: ='Nv capital'!C22 -> 340739.85 | D24: ='Nv capital'!I22 -> 340739.85 | E24: =D24/$D$11 -> 0.014817861 | F24: =$D$9*E24 -> 148061.67 | G24: 0 | H24: =$D$8*G24 -> 0 | I24: ='Avances asso'!C17 -> 0 | J24: =C24+F24+H24-I24 -> 488801.52 | K24: =($J24-($E24*' Bilan cloture'!$D$6))*2.58% -> 11049.174 | L24: =J24 -> 488801.52 | M24: =L24/$L$11 -> 0.014908248
A25: 13 | B25: ='Nv capital'!B23 -> الواهج اسية | C25: ='Nv capital'!C23 -> 513448.84 | D25: ='Nv capital'!I23 -> 513448.84 | E25: =D25/$D$11 -> 0.022328511 | F25: =$D$9*E25 -> 223108.89 | G25: 0 | H25: =$D$8*G25 -> 0 | I25: ='Avances asso'!C18 -> 150000 | J25: =C25+F25+H25-I25 -> 586557.73 | K25: =($J25-($E25*' Bilan cloture'!$D$6))*2.58% -> 12779.61 | L25: =J25 -> 586557.73 | M25: =L25/$L$11 -> 0.017889773
A26: 14 | B26: ='Nv capital'!B24 -> صالح والحاج خوخة | C26: ='Nv capital'!C24 -> 72123.07 | D26: ='Nv capital'!I24 -> 72123.07 | E26: =D26/$D$11 -> 0.0031364386 | F26: =$D$9*E26 -> 31339.633 | G26: 0 | H26: =$D$8*G26 -> 0 | I26: ='Avances asso'!C19 -> 0 | J26: =C26+F26+H26-I26 -> 103462.7 | K26: =($J26-($E26*' Bilan cloture'!$D$6))*2.58% -> 2338.7354 | L26: =J26 -> 103462.7 | M26: =L26/$L$11 -> 0.0031555706
A27: 15 | B27: ='Nv capital'!B25 -> الواهج مامة | C27: ='Nv capital'!E25 -> 500000 | D27: ='Nv capital'!I25 -> 234693.88 | E27: =D27/$D$11 -> 0.010206206 | F27: =$D$9*E27 -> 101981.52 | G27: 0 | H27: =$D$8*G27 -> 0 | I27: ='Avances asso'!C20 -> 0 | J27: =C27+F27+H27-I27 -> 601981.52 | K27: =($J27-($E27*' Bilan cloture'!$D$6))*2.58% -> 14455.318 | L27: =J27 -> 601981.52 | M27: =L27/$L$11 -> 0.018360193
A28: 16 | B28: ='Nv capital'!B26 -> صالح والحاج فاطمة | C28: ='Nv capital'!C26 -> 22034.67 | D28: ='Nv capital'!I26 -> 22034.67 | E28: =D28/$D$11 -> 0.0009582286 | F28: =$D$9*E28 -> 9574.7238 | G28: 0 | H28: =$D$8*G28 -> 0 | I28: ='Avances asso'!C21 -> 0 | J28: =C28+F28+H28-I28 -> 31609.394 | K28: =($J28-($E28*' Bilan cloture'!$D$6))*2.58% -> 714.51842 | L28: =J28 -> 31609.394 | M28: =L28/$L$11 -> 0.00096407372
A29: 17 | B29: ='Nv capital'!B27 -> موسى المال سليمان | C29: ='Nv capital'!C27 -> 642035.45 | D29: ='Nv capital'!I27 -> 642035.45 | E29: =D29/$D$11 -> 0.027920397 | F29: =$D$9*E29 -> 278983.62 | G29: 0 | H29: =$D$8*G29 -> 0 | I29: ='Avances asso'!C22 -> 0 | J29: =C29+F29+H29-I29 -> 921019.07 | K29: =($J29-($E29*' Bilan cloture'!$D$6))*2.58% -> 20819.289 | L29: =J29 -> 921019.07 | M29: =L29/$L$11 -> 0.028090709
A30: 18 | B30: ='Nv capital'!B28 -> باسليمان محمد بن صالح | C30: ='Nv capital'!C28 -> 403492.59 | D30: ='Nv capital'!I28 -> 403492.59 | E30: =D30/$D$11 -> 0.017546809 | F30: =$D$9*E30 -> 175329.61 | G30: 0 | H30: =$D$8*G30 -> 0 | I30: ='Avances asso'!C23 -> 0 | J30: =C30+F30+H30-I30 -> 578822.2 | K30: =($J30-($E30*' Bilan cloture'!$D$6))*2.58% -> 13084.057 | L30: =J30 -> 578822.2 | M30: =L30/$L$11 -> 0.017653843
A31: 19 | B31: ='Nv capital'!B29 -> بن يامي اسلام بن حمزة | C31: ='Nv capital'!E29 -> 70000 | D31: ='Nv capital'!I29 -> 54761.905 | E31: =D31/$D$11 -> 0.0023814481 | F31: =$D$9*E31 -> 23795.687 | G31: 0 | H31: =$D$8*G31 -> 0 | I31: ='Avances asso'!C24 -> 0 | J31: =C31+F31+H31-I31 -> 93795.687 | K31: =($J31-($E31*' Bilan cloture'!$D$6))*2.58% -> 2168.9076 | L31: =J31 -> 93795.687 | M31: =L31/$L$11 -> 0.0028607305
A32: 20 | B32: ='Nv capital'!B30 -> بن يامي محمد بن حمزة | C32: ='Nv capital'!E30 -> 100000 | D32: ='Nv capital'!I30 -> 78231.293 | E32: =D32/$D$11 -> 0.0034020687 | F32: =$D$9*E32 -> 33993.839 | G32: 0 | H32: =$D$8*G32 -> 0 | I32: ='Avances asso'!C25 -> 0 | J32: =C32+F32+H32-I32 -> 133993.84 | K32: =($J32-($E32*' Bilan cloture'!$D$6))*2.58% -> 3098.4394 | L32: =J32 -> 133993.84 | M32: =L32/$L$11 -> 0.0040867579
A33: 21 | B33: ='Nv capital'!B31 -> خن لقمان | C33: ='Nv capital'!E31 -> 110310 | D33: ='Nv capital'!I31 -> 60282.789 | E33: =D33/$D$11 -> 0.0026215365 | F33: =$D$9*E33 -> 26194.677 | G33: 0 | H33: =$D$8*G33 -> 0 | I33: ='Avances asso'!C26 -> 0 | J33: =C33+F33+H33-I33 -> 136504.68 | K33: =($J33-($E33*' Bilan cloture'!$D$6))*2.58% -> 3245.4925 | L33: =J33 -> 136504.68 | M33: =L33/$L$11 -> 0.0041633374
A34: 22 | B34: ='Nv capital'!B32 -> مدرسة فسايل الامل | C34: ='Nv capital'!E32 -> 1200000 | D34: ='Nv capital'!I32 -> 927891.16 | E34: =D34/$D$11 -> 0.040351494 | F34: =$D$9*E34 -> 403196.49 | G34: 0 | H34: =$D$8*G34 -> 0 | I34: ='Avances asso'!C27 -> 0 | J34: =C34+F34+H34-I34 -> 1603196.5 | K34: =($J34-($E34*' Bilan cloture'!$D$6))*2.58% -> 37109.142 | L34: =J34 -> 1603196.5 | M34: =L34/$L$11 -> 0.048896844
A35: 23 | B35: ='Nv capital'!B33 -> الواهج فاطمة الزهراء | C35: ='Nv capital'!E33 -> 100000 | D35: ='Nv capital'!I33 -> 5668.9342 | E35: =D35/$D$11 -> 0.00024652672 | F35: =$D$9*E35 -> 2463.3216 | G35: 0 | H35: =$D$8*G35 -> 0 | I35: ='Avances asso'!C28 -> 0 | J35: =C35+F35+H35-I35 -> 102463.32 | K35: =($J35-($E35*' Bilan cloture'!$D$6))*2.58% -> 2617.5681 | L35: =J35 -> 102463.32 | M35: =L35/$L$11 -> 0.0031250898
A36: 24 | B36: ='Nv capital'!B34 -> الواهج لالة | C36: ='Nv capital'!E34 -> 180000 | D36: ='Nv capital'!I34 -> 94693.878 | E36: =D36/$D$11 -> 0.0041179823 | F36: =$D$9*E36 -> 41147.325 | G36: 0 | H36: =$D$8*G36 -> 0 | I36: ='Avances asso'!C29 -> 0 | J36: =C36+F36+H36-I36 -> 221147.32 | K36: =($J36-($E36*' Bilan cloture'!$D$6))*2.58% -> 5271.5371 | L36: =J36 -> 221147.32 | M36: =L36/$L$11 -> 0.0067449039
A37: 25 | B37: ='Nv capital'!B35 -> صالح والحاج ادريس بن سليمان | C37: ='Nv capital'!E35 -> 100000 | D37: ='Nv capital'!I35 -> 21768.707 | E37: =D37/$D$11 -> 0.00094666261 | F37: =$D$9*E37 -> 9459.1551 | G37: 0 | H37: =$D$8*G37 -> 0 | I37: ='Avances asso'!C30 -> 0 | J37: =C37+F37+H37-I37 -> 109459.16 | K37: =($J37-($E37*' Bilan cloture'!$D$6))*2.58% -> 2724.2614 | L37: =J37 -> 109459.16 | M37: =L37/$L$11 -> 0.0033384599
A38: 26 | B38: ='Nv capital'!B36 -> صالح والحاج سليمان بن عمر | C38: ='Nv capital'!E36 -> 100000 | D38: ='Nv capital'!I36 -> 90249.433 | E38: =D38/$D$11 -> 0.0039247054 | F38: =$D$9*E38 -> 39216.081 | G38: 0 | H38: =$D$8*G38 -> 0 | I38: ='Avances asso'!C31 -> 0 | J38: =C38+F38+H38-I38 -> 139216.08 | K38: =($J38-($E38*' Bilan cloture'!$D$6))*2.58% -> 3178.0837 | L38: =J38 -> 139216.08 | M38: =L38/$L$11 -> 0.0042460341
A39: 27 | B39: ='Nv capital'!B37 -> صالح والحاج سليمان ين عمر | C39: ='Nv capital'!E37 -> 500000 | D39: ='Nv capital'!I37 -> 157596.37 | E39: =D39/$D$11 -> 0.0068534428 | F39: =$D$9*E39 -> 68480.342 | G39: 0 | H39: =$D$8*G39 -> 0 | I39: ='Avances asso'!C32 -> 0 | J39: =C39+F39+H39-I39 -> 568480.34 | K39: =($J39-($E39*' Bilan cloture'!$D$6))*2.58% -> 13944.392 | L39: =J39 -> 568480.34 | M39: =L39/$L$11 -> 0.01733842
A40: 28 | B40: ='Nv capital'!B38 -> طالب باحمد نانة | C40: ='Nv capital'!E38 -> 40000 | D40: ='Nv capital'!I38 -> 21859.41 | E40: =D40/$D$11 -> 0.00095060703 | F40: =$D$9*E40 -> 9498.5683 | G40: 0 | H40: =$D$8*G40 -> 0 | I40: ='Avances asso'!C33 -> 0 | J40: =C40+F40+H40-I40 -> 49498.568 | K40: =($J40-($E40*' Bilan cloture'!$D$6))*2.58% -> 1176.8625 | L40: =J40 -> 49498.568 | M40: =L40/$L$11 -> 0.0015096863
A41: 29 | B41: ='Nv capital'!B39 -> النادي الرياضي فسائل الامل | C41: ='Nv capital'!E39 -> 100000 | D41: ='Nv capital'!I39 -> 73696.145 | E41: =D41/$D$11 -> 0.0032048474 | F41: =$D$9*E41 -> 32023.181 | G41: 0 | H41: =$D$8*G41 -> 0 | I41: ='Avances asso'!C34 -> 0 | J41: =C41+F41+H41-I41 -> 132023.18 | K41: =($J41-($E41*' Bilan cloture'!$D$6))*2.58% -> 3068.385 | L41: =J41 -> 132023.18 | M41: =L41/$L$11 -> 0.0040266536
A42: 30 | B42: ='Nv capital'!B40 -> الواهج عمر بن يحي بن حمو | C42: ='Nv capital'!C40 -> 1547888.9 | D42: ='Nv capital'!I40 -> 1547888.9 | E42: =D42/$D$11 -> 0.067313531 | F42: =$D$9*E42 -> 672604.08 | G42: 0 | H42: =$D$8*G42 -> 0 | I42: ='Avances asso'!C35 -> 0 | J42: =C42+F42+H42-I42 -> 2220493 | K42: =($J42-($E42*' Bilan cloture'!$D$6))*2.58% -> 50193.407 | L42: =J42 -> 2220493 | M42: =L42/$L$11 -> 0.067724138

Sheet Avances asso
A2: مقدم أرباح الشركاء لسنة 2020
A4: المجموع | C4: =SUM(C6:C104) -> 20808199
A5: رقم | B5: الشركاء | C5: مقدم أرباح الشركاء
A6: 1 | B6: ='Nv capital'!B11 -> الواهج عمر بن يحي | C6: =6179240.63+13708958 -> 19888199
A7: =IF(B6<>B7,A6+1,A6) -> 2 | B7: ='Nv capital'!B12 -> بن عزوز مبخوتة | C7: 500000
A8: =IF(B7<>B8,A7+1,A7) -> 3 | B8: ='Nv capital'!B13 -> كروشي الحاج بابهون | C8: 0
A9: 4 | B9: ='Nv capital'!B14 -> بوسربة ياسمينة | C9: 0
A10: 5 | B10: ='Nv capital'!B15 -> بعوشي رسثم | C10: 200000
A11: 6 | B11: ='Nv capital'!B16 -> بوسريح نعيمة
A12: 7 | B12: ='Nv capital'!B17 -> بكاير حرمية بنت محمد
A13: 8 | B13: ='Nv capital'!B18 -> بكاير رابح بن محمد
A14: 9 | B14: ='Nv capital'!B19 -> لعساكر عبد الحميد | C14: 70000
A15: 10 | B15: ='Nv capital'!B20 -> الواهج احمد
A16: 11 | B16: ='Nv capital'!B21 -> مبروك مبروك طولقة
A17: 12 | B17: ='Nv capital'!B22 -> بن يامي فؤاد بن علي
A18: 13 | B18: الواهج اسية | C18: 150000
A19: 14 | B19: صالح والحاج خوخة
A20: 15 | B20: صالح والحاج خوخة
A21: 16 | B21: صالح والحاج فاطمة
A22: 17 | B22: موسى المال سليمان
A23: 18 | B23: باسليمان محمد بن صالح

Sheet Fiche associé
D9: N°
B10: =LOOKUP($D$10,'Repartition globale'!$A$13:$A$44,'Repartition globale'!$B$13:$B$44) -> الواهج عمر بن يحي | C10: هذا بيان حساب السيد: | D10: 1
B11: في محل صياغة الفتح الى تاريخ 13 ربيع الثاني 1446 ه
A13: Capital investi: | B13: =SUMIF('Repartition globale'!$A$13:$A$46,'Fiche associé'!$D$10,'Repartition globale'!$C$13:$D$46) -> 0 | C13: رأس المال المستثمر:
A14: Capital parapport nbr jours ouvrés | B14: =SUMIF('Repartition globale'!$A$13:$A$46,'Fiche associé'!$D$10,'Repartition globale'!$D$13:$D$46) -> 0 | C14: رأس المال العامل بالنسبة لعدد الأيام:
A15: BENEFICE DU CAPITAL : | B15: =SUMIF('Repartition globale'!$A$13:$A$46,'Fiche associé'!$D$10,'Repartition globale'!$F$13:$F$46) -> 0 | C15: أرباح مقابل المال :
A16: Rentabilité des capiteaux: | B16: =B15/B14 -> #DIV/0! | C16: مردودية رأس المال:
A17: BENEFICE DE L'EFFORT: | B17: =SUMIF('Repartition globale'!$A$13:$A$46,'Fiche associé'!$D$10,'Repartition globale'!$H$13:$H$46) -> 9992108.1 | C17: أرباح مقابل الجهد :
A18: Avances associés: | B18: =SUMIF('Repartition globale'!$A$13:$A$46,'Fiche associé'!$D$10,'Repartition globale'!$I$13:$I$46) -> 19888199 | C18: مقدم الأرباح:
A19: TOTAL: | B19: =SUMIF('Repartition globale'!$A$13:$A$46,'Fiche associé'!$D$10,'Repartition globale'!$J$13:$J$46) -> -9896090.5 | C19: المجموع :
A20: ZAKAT: | B20: =SUMIF('Repartition globale'!$A$13:$A$46,'Fiche associé'!$D$10,'Repartition globale'!$K$13:$K$46) -> 0 | C20: زكاة السنة التجارية:
A21: NOUVEAU CAPITAL : | B21: =SUMIF('Repartition globale'!$A$13:$A$46,'Fiche associé'!$D$10,'Repartition globale'!$L$13:$L$46) -> 0 | C21: رأس المال الجديد :

Sheet  Bilan départ
A1: ="الميزانية الافتتاحية لمؤسسة "&Données!B1&" في "&DAY(Données!$B$6+1)&"/"&MONTH(Données!$B$6+1)&"/"&YEAR(Données!$B$6+1) -> الميزانية الافتتاحية لمؤسسة صياغة الفتح في 19/10/2024
A3: Actif / الأصول | F3: Passif / الخصوم
A4: Code | B4: Libéllé de l'Opération | D4: Montant | F4: Code | G4: Libéllé de l'Opération | I4: Montant
A5: Compta | F5: Compta
A6: =D6/D27 -> 0.06911239 | B6: Investissement / الاستثمارات | D6: =SUM(D7:D10) -> 4085540 | F6: =I6/I27 -> 0.33993723 | G6: Fonds Propres / رؤوس الأموال | I6: =SUM(I7:I10) -> 18656474
A7: 2 | B7: =IF(' Bilan cloture'!B7="","",' Bilan cloture'!B7) -> Materiels & équipements | C7: =IF(' Bilan cloture'!C7="","",' Bilan cloture'!C7) -> التجهيزات | D7: =' Bilan cloture'!D7 -> 569310 | F7: 1 | G7: =IF(' Bilan cloture'!G7="","",' Bilan cloture'!G7) -> Capiteaux des associés | H7: =IF(' Bilan cloture'!H7="","",' Bilan cloture'!H7) -> رؤوس أموال الشركاء | I7: ='Repartition globale'!L11-SUM('Repartition globale'!G7:H8) -> 18656474
B8: =IF(' Bilan cloture'!B8="","",' Bilan cloture'!B8) -> Matériel Roulant | C8: =IF(' Bilan cloture'!C8="","",' Bilan cloture'!C8) -> معدات النقل | D8: =' Bilan cloture'!D8 -> 2000000 | G8: =IF(' Bilan cloture'!G8="","",' Bilan cloture'!G8) | H8: =IF(' Bilan cloture'!H8="","",' Bilan cloture'!H8)
B9: =IF(' Bilan cloture'!B9="","",' Bilan cloture'!B9) -> Materiels & équipements | C9: =IF(' Bilan cloture'!C9="","",' Bilan cloture'!C9) -> التجهيزات | D9: =' Bilan cloture'!D9 -> 1516230 | G9: =IF(' Bilan cloture'!G9="","",' Bilan cloture'!G9) | H9: =IF(' Bilan cloture'!H9="","",' Bilan cloture'!H9)
B10: =IF(' Bilan cloture'!B10="","",' Bilan cloture'!B10) -> Materiels & équipements | C10: =IF(' Bilan cloture'!C10="","",' Bilan cloture'!C10) -> التجهيزات | D10: =' Bilan cloture'!D10 -> 0 | G10: =IF(' Bilan cloture'!G10="","",' Bilan cloture'!G10) | H10: =IF(' Bilan cloture'!H10="","",' Bilan cloture'!H10)
A11: =D11/D27 -> 0.61981244 | B11: Stocks / المخزونات | D11: =SUM(D12:D13) -> 36639863 | F11: =I11/I27 -> 0.66006277 | G11: Dettes / الديون | I11: =SUM(I12:I18) -> 36225640
A12: 3 | B12: =IF(' Bilan cloture'!B12="","",' Bilan cloture'!B12) -> Stocks Marchandises OR | C12: =IF(' Bilan cloture'!C12="","",' Bilan cloture'!C12) -> مخزون السلع | D12: =' Bilan cloture'!D12 -> 36489863 | F12: 4 | G12: =IF(' Bilan cloture'!G12="","",' Bilan cloture'!G12) -> Dettes Fournisseurs | H12: =IF(' Bilan cloture'!H12="","",' Bilan cloture'!H12) -> ديون الموردين | I12: =' Bilan cloture'!I12 -> 2441869.1
B13: =IF(' Bilan cloture'!B14="","",' Bilan cloture'!B14) -> Stocks Marchandises P/O | C13: =IF(' Bilan cloture'!C14="","",' Bilan cloture'!C14) | D13: =' Bilan cloture'!D14 -> 150000 | G13: =IF(' Bilan cloture'!G14="","",' Bilan cloture'!G14) -> Dettes Fournisseurs Casse | H13: =IF(' Bilan cloture'!H14="","",' Bilan cloture'!H14) -> ديون الموردين | I13: =' Bilan cloture'!I14 -> 11721510
A14: =D14/D27 -> 0.29295164 | B14: Créances / الحقوق | D14: =SUM(D15:D22) -> 17317671 | G14: =IF(' Bilan cloture'!G15="","",' Bilan cloture'!G15) -> Avances clients (versements) | H14: =IF(' Bilan cloture'!H15="","",' Bilan cloture'!H15) -> تسبيقات الزبائن | I14: =' Bilan cloture'!I15 -> 16543749
A15: 4 | B15: =IF(' Bilan cloture'!B16="","",' Bilan cloture'!B16) -> Créances Clients | C15: =IF(' Bilan cloture'!C16="","",' Bilan cloture'!C16) -> مستحقات لدى الزبائن | D15: =' Bilan cloture'!D16 -> 5829108 | G15: =IF(' Bilan cloture'!G16="","",' Bilan cloture'!G16) -> Avances clients Casse | H15: =IF(' Bilan cloture'!H16="","",' Bilan cloture'!H16) -> تسبيقات الزبائن | I15: =' Bilan cloture'!I16 -> 5106570
B16: =IF(' Bilan cloture'!B17="","",' Bilan cloture'!B17) -> Créances Clients Casse | C16: =IF(' Bilan cloture'!C17="","",' Bilan cloture'!C17) -> مستحقات لدى الزبائن | D16: =' Bilan cloture'!D17 -> 9715 | G16: =IF(' Bilan cloture'!G17="","",' Bilan cloture'!G17) -> Dettes Personnel | H16: =IF(' Bilan cloture'!H17="","",' Bilan cloture'!H17) | I16: =' Bilan cloture'!I17 -> 411941.5
B17: =IF(' Bilan cloture'!B18="","",' Bilan cloture'!B18) -> Avances fournisseurs | C17: =IF(' Bilan cloture'!C18="","",' Bilan cloture'!C18) -> تسبيقات للموردين | D17: =' Bilan cloture'!D18 -> 267528.62 | G17: =IF(' Bilan cloture'!G18="","",' Bilan cloture'!G18) -> Dettes Inpot Tripinal Berriane | H17: =IF(' Bilan cloture'!H18="","",' Bilan cloture'!H18) | I17: =' Bilan cloture'!I18 -> 0
B18: =IF(' Bilan cloture'!B19="","",' Bilan cloture'!B19) -> Avances fournisseurs Casse 18 | C18: =IF(' Bilan cloture'!C19="","",' Bilan cloture'!C19) -> تسبيقات للموردين | D18: =' Bilan cloture'!D19 -> 1271360 | G18: =IF(' Bilan cloture'!G19="","",' Bilan cloture'!G19) | H18: =IF(' Bilan cloture'!H19="","",' Bilan cloture'!H19) | I18: =' Bilan cloture'!I19 -> 0
B19: =IF(' Bilan cloture'!B21="","",' Bilan cloture'!B21) -> Avances associers | C19: =IF(' Bilan cloture'!C21="","",' Bilan cloture'!C21) -> تسبيقات للشركاء
B20: =IF(' Bilan cloture'!B22="","",' Bilan cloture'!B22) -> Prêt salariés | C20: =IF(' Bilan cloture'!C22="","",' Bilan cloture'!C22) -> سلف للعمال | D20: =' Bilan cloture'!D22 -> 43869
B21: Avance associé Omar Louhedj 2016 | D21: =-'Repartition globale'!J13 -> 9896090.5
A23: =D23/D27 -> 0.01812353 | B23: Disponibilités / السيولة | D23: =SUM(D24:D26) -> 1071362.3
A24: 5 | B24: =IF(' Bilan cloture'!B26="","",' Bilan cloture'!B26) -> Trésorie | C24: =IF(' Bilan cloture'!C26="","",' Bilan cloture'!C26) -> الخزينة | D24: =' Bilan cloture'!D26 -> 775910
B25: =IF(' Bilan cloture'!B27="","",' Bilan cloture'!B27) -> Compte courant Banque BDL | C25: =IF(' Bilan cloture'!C27="","",' Bilan cloture'!C27) -> الحساب الجاري البنكي | D25: =' Bilan cloture'!D27 -> 15452.28
B26: =IF(' Bilan cloture'!B28="","",' Bilan cloture'!B28) -> Devise-euro | C26: =IF(' Bilan cloture'!C28="","",' Bilan cloture'!C28) -> 1120 | D26: =' Bilan cloture'!D28 -> 280000
B27: Total Actif | D27: =D6+D11+D14+D23 -> 59114437 | F27: Total Passif | I27: =I11+I6 -> 54882113 | J27: =D27-I27 -> 4232323.2

Sheet stoks arg
G1: =SUM(G5:G38167) -> 3044406.9
D3: =SUBTOTAL(9,D5:D160) -> 12910.36 | G3: =SUBTOTAL(9,G5:G153) -> 3044406.9
A4: N° | B4: articles | C4: Ref | D4: poid | E4: Quant | F4: prix U | G4: somme
A5: 1 | B5: argent mar.925 | D5: =10+130+107.9+88.5+151.6+30+595.49+2.59+347.15+513.47+280.43+386.7+358.99+561.64+348.8+407.45+195.13+250.19+213.98+287.86 -> 5267.87 | F5: 350 | G5: =D5*F5 -> 1843754.5
A6: 1 | B6: argent mar.500 | D6: =105.26+22.62+54.09+7.3+15.6+40.13+54+218.07+56+40+99+120+85+512.58+299.36+225.15+8+134.78+393.3+79.3+60+49.46+34.77+192.75+354+628.1 -> 3888.62 | F6: 220 | G6: =D6*F6 -> 855496.4
A7: 1 | B7: argent casse.500 | D7: =156.71+95+109.14+230.7+23.1+26.32+2.97+14.26+543.9+566.48+381.2+477+85.65+80.92+118.5 -> 2911.85 | F7: 100 | G7: =D7*F7 -> 291185
A8: 1 | B8: argent casse.250 | D8: 782.67 | F8: 50 | G8: =D8*F8 -> 39133.5
A9: 2 | B9: argent casse.999 | D9: =27.35+32 -> 59.35 | F9: 250 | G9: =D9*F9 -> 14837.5
A10: 2 | G10: =E10*F10 -> 0
A11: 3 | G11: =E11*F11 -> 0
A12: 3 | G12: =E12*F12 -> 0
A13: 4 | G13: =E13*F13 -> 0
A14: 5 | G14: =E14*F14 -> 0
A15: 6 | G15: =E15*F15 -> 0
A16: 7 | G16: =E16*F16 -> 0
A17: 8 | G17: =E17*F17 -> 0
A18: 9 | G18: =E18*F18 -> 0
A19: 10 | G19: =E19*F19 -> 0
A20: 11 | G20: =E20*F20 -> 0
A21: 12 | G21: =E21*F21 -> 0
... A34: 20 | G34: =E34*F34 -> 0
A35: 21
A36: 22
A37: 23
A38: 24
A39: 25
A40: 26
A41: 27
A42: 28
A43: 29
A44: 29

Sheet stok PO
G1: =SUM(G5:G38166) -> 150000
D3: =SUBTOTAL(9,D5:D159) -> 0 | G3: =SUBTOTAL(9,G5:G152) -> 150000
A4: N° | B4: articles | C4: Ref | D4: poid | E4: Quant | F4: prix U | G4: somme
A5: 1 | B5: Parure | G5: =E5*F5 -> 0
A6: 1 | B6: perles | C6: djouher | G6: =E6*F6 -> 0
A7: 1 | B7: perles | C7: zazaghe | G7: =E7*F7 -> 0
A8: 1 | B8: perles | C8: colier harme | G8: =E8*F8 -> 0
A9: 2 | B9: perles | C9: coraille | G9: =E9*F9 -> 0
A10: 2 | B10: embalage | C10: lux
A11: 3 | B11: Plaqué or | C11: Divers | G11: 150000
A12: 3
A13: 4
A14: 5
A15: 6
A16: 7
A17: 8
A18: 9
A19: 10
A20: 11
A21: 12
A22: 13
A23: 14
... A43: 29

Sheet stocks or
I1: =SUM(I5:I38156) -> 36489863
C3: =SUBTOTAL(9,C5:C148) -> 1995.69 | D3: =SUBTOTAL(9,D5:D148) -> 267.88 | I3: =SUBTOTAL(9,I5:I142) -> 36489863
A4: N° | B4: articles | C4: poid(g)or | D4: poid(g)or | E4: Ref | F4: Quant | G4: prix casse | H4: prix façon | I4: somme
A5: 1 | B5: balieure et recube MAG | D5: 75 | G5: 14500 | I5: =D5*G5 -> 1087500
A6: 2 | B6: casse18 | I6: =D6*G6 -> 0
A7: 3 | B7: casse18 | D7: =5.02+28.56+69+1.31+5.63+3.5+1.82+4.08+5.08+6.19+5.24 -> 135.43 | G7: 14500 | I7: =D7*G7 -> 1963735
A8: 4 | B8: casse21 | D8: =0.53+3.84+21.78 -> 26.15 | G8: 16500 | I8: =D8*G8 -> 431475
A9: 5 | B9: or 750 | C9: =4.57+2.85+2.94+3.18+2.58+2.47+1.23+42.72+2.3+1.82+1.8+34.37+45.02 -> 147.85 | E9: itali | G9: 15000 | H9: 3000 | I9: =C9*(G9+H9) -> 2661300
A10: 5 | B10: or 750 | C10: =31.03+27.27+20.29+29.53+10.63+3.28+8.11+10.65+3.95+6.79+9.77+9.43+3.83+8.18+2.14+40.83+72.9+25.52 -> 324.13 | E10: itali | G10: 15000 | H10: 3500 | I10: =C10*(G10+H10) -> 5996405
A11: 6 | B11: or 750 | C11: =31.59+16.09 -> 47.68 | E11: local PS | G11: 15000 | H11: 1500 | I11: =C11*(G11+H11) -> 786720
A12: 7 | B12: or 750 | C12: =19.03+11.03 -> 30.06 | E12: local SPS | G12: 15000 | H12: 1150 | I12: =C12*(G12+H12) -> 485469
A13: 8 | B13: or articles | C13: =1.24+2.15+1.32+3.41+1.41+12.33+3.09+2.06+3.43+2.56+1.25+2.93+2.28+1.54+2.15+14.28+2.3+4.58+7.35+7.56+53.43+17.67+21.82+2.12+8.03+8.84+12.16+2.25+7.8+11.7+8+3.39+6.16+38.04+24.79+47.56+12.22+30.4+53.78+56.87+53.61+30.05+26.32+15.79+21.49+20.35+14.32+4.92+14.16+75.14+48.7+21.36+5.58+39.02 -> 897.06 | E13: SP | G13: 14500 | H13: 1200 | I13: =C13*(G13+H13) -> 14083842
A14: 9 | B14: or articles | C14: =16.05+30+30+17.13+30.18 -> 123.36 | E14: mesaise | G14: 14500 | H14: 650 | I14: =C14*(G14+H14) -> 1868904
A15: 10 | B15: or articles | C15: =22.14+30+30.14+11.12 -> 93.4 | E15: mesaise | G15: 14500 | H15: 750 | I15: =C15*(G15+H15) -> 1424350
B16: or articles | C16: 60.09 | E16: mesaise local PS | G16: 15300 | H16: 750 | I16: =C16*(G16+H16) -> 964444.5
B17: or articles | C17: 20 | E17: mesaise local PS | G17: 15300 | H17: 850 | I17: =C17*(G17+H17) -> 323000
A18: 11 | B18: or articles | C18: =1.4+5.35+2.24+2.62+3.83+0.85+3.47+22.94+1.32+4.83+5.69+4.23+2.4+12.9 -> 74.07 | E18: AVP | G18: 14500 | H18: 800 | I18: =C18*(G18+H18) -> 1133271
A19: 12 | B19: or articles | E19: PL | I19: =(G19+H19)*D19 -> 0
A20: 13 | B20: or articles | C20: =2+4+3+27.77+32.87+3.96 -> 73.6 | E20: louice | G20: 14500 | H20: 500 | I20: =C20*(G20+H20) -> 1104000
A21: 14 | B21: or articles | C21: 47.52 | E21: mesaise | G21: 14700 | H21: 680 | I21: =C21*(G21+H21) -> 730857.6
A22: 15 | B22: or fin | D22: 6.32 | G22: 18500 | I22: =D22*G22 -> 116920
A23: 16 | B23: or articles.21 | D23: =4.21+4.5+7.25+9.02 -> 24.98 | G23: 19000 | I23: =D23*G23 -> 474620
B24: or articles | C24: 56.87 | E24: bague solitaire | G24: 14500 | H24: 500 | I24: =C24*(G24+H24) -> 853050

Sheet client
B1: Prix casse 18 | C1: 14500 | F1: =SUM(F6:F359)*C1 -> 9715 | G1: =SUM(G6:G359)*C1+H3 -> 5106570 | I1: =SUM(I6:I359) -> 5829108 | J1: =SUM(J6:J359) -> 16543749
B2: Prix casse 21 | C2: 16500
E3: =E4*C2 -> 0 | F3: =F4*C1 -> 9715 | G3: =G4*C1 -> 4350870 | H3: =H4*C2 -> 755700 | I3: =SUBTOTAL(9,I6:I360) -> 5829108 | J3: =SUBTOTAL(9,J6:J360) -> 16543749
E4: =SUBTOTAL(9,E6:E361) -> 0 | F4: =SUBTOTAL(9,F6:F361) -> 0.67 | G4: =SUBTOTAL(9,G6:G361) -> 300.06 | H4: =SUBTOTAL(9,H6:H361) -> 45.8
A5: N° | B5: client | C5: téléphone | D5: adresse | E5: Creance casse21 | F5: Creance casse18 | G5: dette casse18 | H5: dette casse21 | I5: Creance | J5: dette
A6: 1 | B6: client divers | F6: 0.67 | G6: 300.06 | H6: 45.8
A7: 2 | B7: client divers | I7: 5441263 | J7: 16543749
A8: 3 | B8: client divers reparation | I8: 68845 | K8: 257.02
A9: 4 | B9: client divers dorure | I9: 19000
A10: 4 | B10: debouz hadj kacem | I10: 300000
A11: 5
A12: 6
A13: 7
A14: 8
A15: 9
A16: 10
A17: 11
A18: 13
A19: 14
A20: 15
A21: 16
A22: 17
... A189: 184

Sheet Frs
F2: =SUM(F7:F3205)*$C$3 -> 1271360 | G2: =G4+H4 -> 11721510 | I2: =SUM(I7:I312) -> 267528.62 | J2: =SUM(J7:J312) -> 2441869.1
B3: Prix casse 18 | C3: 14500
B4: Prix casse 21 | C4: 16500 | E4: =E5*C4 -> 964260 | F4: =F5*C3 -> 1271360 | G4: =G5*C3 -> 11721510 | H4: =H5*C4 -> 0 | I4: =SUBTOTAL(9,I6:I315) -> 267528.62 | J4: =SUBTOTAL(9,J6:J315) -> 2441869.1
E5: =SUBTOTAL(9,E7:E316) -> 58.44 | F5: =SUBTOTAL(9,F7:F316) -> 87.68 | G5: =SUBTOTAL(9,G7:G316) -> 808.38 | H5: =SUBTOTAL(9,H7:H316) -> 0
A6: N° | B6: fourniseure | C6: téléphone | D6: adresse | E6: Creance casse21 | F6: Creance casse18 | G6: dette casse18 | H6: dette casse21 | I6: Creance | J6: dette
A7: 1 | B7: At b1 yahia | E7: 14.52 | G7: 44.61 | J7: 684487.22
A8: 2 | B8: Ben abdellah bakir | F8: 9.12 | I8: 1957.34
A9: 3 | B9: At b2 Or | G9: 227.11 | J9: 288716
A10: 4 | B10: At b2 | J10: 1292728.6
A11: 5 | B11: babker abdelaziz/M2 | J11: 16900
A12: 6 | B12: Ben yami omar | G12: 68.39 | J12: 9190.5
A13: 7 | B13: Rachid batna | G13: 168.68 | J13: =3895.5+4000 -> 7895.5
A14: 8 | B14: Azghar moussa | G14: 62.71 | J14: 10721.9
A15: 9 | B15: Hamza 750 | G15: 117.07
A16: 10 | B16: Ghecham malik | G16: 64.7 | K16: 247.46
A17: 11 | B17: Hakim drisi | G17: 34.96 | I17: 57320
A18: 12 | B18: salah arg | J18: 120000
A19: 13 | B19: Khettara med | E19: 43.56 | F19: 77.04 | G19: 18.28 | J19: 11229.4
A20: 14 | B20: magasin elfeth ghardaia | I20: 122100
A21: 15 | B21: Khaled ben azouz | E21: 0.36 | I21: 528
A22: 16 | B22: babker abdelaziz | G22: 1.87 | I22: 64623.28
A23: 17 | B23: med djelfa | F23: 1.52 | I23: 21000

Sheet personnel
H4: =SUBTOTAL(9,H6:H29917) -> 43869 | I4: =SUBTOTAL(9,I6:I29917) -> 411941.5 | J4: =SUBTOTAL(9,J6:J29917) -> 0 | K4: =SUBTOTAL(9,K6:K29917) -> 0
A5: N° | B5: Bon | C5: date | D5: Non et prenom | E5: téléphone | F5: Réf | G5: désignation | H5: creance | I5: dette | J5: Entrée | K5: sortie
A6: 1 | D6: Moussalmal slimen | I6: 268241.5
A7: 6 | D7: Moussalmal yemma | I7: 143700
A8: 5 | D8: Louahedj ahmed | H8: 43869
A9: 8
A10: 9
A11: 10
A12: 11
A13: 12
A14: 13
A15: 14
A16: 15
A17: 16
A18: 17
A19: 18
A20: 19
A21: 20

Sheet Invest Mag
A1: Aménagement | S1: Aménagement | T1: =SUMIF($B$10:$B$1429,S1,$T$10:$T$14029) -> 65333.333 | AG1: Aménagement | AH1: =SUMIF($B$10:$B$1429,AG1,$AH$10:$AH$14029) -> 49333.333 | AU1: Aménagement | AV1: =SUMIF($B$10:$B$1429,AU1,$AV$10:$AV$14029) -> 52200 | BI1: Aménagement | BJ1: =SUMIF($B$10:$B$1429,BI1,$BJ$10:$BJ$14029) -> 32700 | BW1: Aménagement | BX1: =SUMIF($B$10:$B$1429,BW1,$BX$10:$BX$14029) -> 13200 | CK1: Aménagement | CL1: =SUMIF($B$10:$B$1429,CK1,$CL$10:$CL$14029) -> 9200 | CY1: Aménagement | CZ1: =SUMIF($B$10:$B$1429,CY1,$CZ$10:$CZ$14029) -> 4866.6667 | DM1: Aménagement | DN1: =SUMIF($B$10:$B$1429,DM1,$DN$10:$DN$14029) -> 4583.3333 | EA1: Aménagement | EB1: =SUMIF($B$10:$B$1429,EA1,$EB$10:$EB$14029) -> 4650
A2: Equipements | C2: Première année amortissement | E2: 41944 | S2: Equipements | T2: =SUMIF($B$10:$B$1429,S2,$T$10:$T$14029) -> 0 | AG2: Equipements | AH2: =SUMIF($B$10:$B$1429,AG2,$AH$10:$AH$14029) -> 0 | AU2: Equipements | AV2: =SUMIF($B$10:$B$1429,AU2,$AV$10:$AV$14029) -> 0 | BI2: Equipements | BJ2: =SUMIF($B$10:$B$1429,BI2,$BJ$10:$BJ$14029) -> 0 | BW2: Equipements | BX2: =SUMIF($B$10:$B$1429,BW2,$BX$10:$BX$14029) -> 0 | CK2: Equipements | CL2: =SUMIF($B$10:$B$1429,CK2,$CL$10:$CL$14029) -> 0 | CY2: Equipements | CZ2: =SUMIF($B$10:$B$1429,CY2,$CZ$10:$CZ$14029) -> 0 | DM2: Equipements | DN2: =SUMIF($B$10:$B$1429,DM2,$DN$10:$DN$14029) -> 0 | EA2: Equipements | EB2: =SUMIF($B$10:$B$1429,EA2,$EB$10:$EB$14029) -> 0
A3: Matériels | S3: Matériels | T3: =SUMIF($B$10:$B$1429,S3,$T$10:$T$14029) -> 0 | AG3: Matériels | AH3: =SUMIF($B$10:$B$1429,AG3,$AH$10:$AH$14029) -> 0 | AU3: Matériels | AV3: =SUMIF($B$10:$B$1429,AU3,$AV$10:$AV$14029) -> 41976.944 | BI3: Matériels | BJ3: =SUMIF($B$10:$B$1429,BI3,$BJ$10:$BJ$14029) -> 173996.94 | BW3: Matériels | BX3: =SUMIF($B$10:$B$1429,BW3,$BX$10:$BX$14029) -> 129973.61 | CK3: Matériels | CL3: =SUMIF($B$10:$B$1429,CK3,$CL$10:$CL$14029) -> 105973.61 | CY3: Matériels | CZ3: =SUMIF($B$10:$B$1429,CY3,$CZ$10:$CZ$14029) -> 54113.333 | DM3: Matériels | DN3: =SUMIF($B$10:$B$1429,DM3,$DN$10:$DN$14029) -> 50493.333 | EA3: Matériels | EB3: =SUMIF($B$10:$B$1429,EA3,$EB$10:$EB$14029) -> 57733.333
A4: Mobilier | S4: Mobilier | T4: =SUMIF($B$10:$B$1429,S4,$T$10:$T$14029) -> 0 | AG4: Mobilier | AH4: =SUMIF($B$10:$B$1429,AG4,$AH$10:$AH$14029) -> 0 | AU4: Mobilier | AV4: =SUMIF($B$10:$B$1429,AU4,$AV$10:$AV$14029) -> 0 | BI4: Mobilier | BJ4: =SUMIF($B$10:$B$1429,BI4,$BJ$10:$BJ$14029) -> 0 | BW4: Mobilier | BX4: =SUMIF($B$10:$B$1429,BW4,$BX$10:$BX$14029) -> 0 | CK4: Mobilier | CL4: =SUMIF($B$10:$B$1429,CK4,$CL$10:$CL$14029) -> 0 | CY4: Mobilier | CZ4: =SUMIF($B$10:$B$1429,CY4,$CZ$10:$CZ$14029) -> 0 | DM4: Mobilier | DN4: =SUMIF($B$10:$B$1429,DM4,$DN$10:$DN$14029) -> 0 | EA4: Mobilier | EB4: =SUMIF($B$10:$B$1429,EA4,$EB$10:$EB$14029) -> 0
A5: Résidence | S5: Résidence | T5: =SUMIF($B$10:$B$1429,S5,$T$10:$T$14029) -> 0 | AG5: Résidence | AH5: =SUMIF($B$10:$B$1429,AG5,$AH$10:$AH$14029) -> 0 | AU5: Résidence | AV5: =SUMIF($B$10:$B$1429,AU5,$AV$10:$AV$14029) -> 0 | BI5: Résidence | BJ5: =SUMIF($B$10:$B$1429,BI5,$BJ$10:$BJ$14029) -> 0 | BW5: Résidence | BX5: =SUMIF($B$10:$B$1429,BW5,$BX$10:$BX$14029) -> 0 | CK5: Résidence | CL5: =SUMIF($B$10:$B$1429,CK5,$CL$10:$CL$14029) -> 0 | CY5: Résidence | CZ5: =SUMIF($B$10:$B$1429,CY5,$CZ$10:$CZ$14029) -> 0 | DM5: Résidence | DN5: =SUMIF($B$10:$B$1429,DM5,$DN$10:$DN$14029) -> 0 | EA5: Résidence | EB5: =SUMIF($B$10:$B$1429,EA5,$EB$10:$EB$14029) -> 0
A6: Matériel Roulant | T6: =SUMIF($B$10:$B$1429,S6,$T$10:$T$14029) -> 0 | AH6: =SUMIF($B$10:$B$1429,AG6,$AH$10:$AH$14029) -> 0 | AV6: =SUMIF($B$10:$B$1429,AU6,$AV$10:$AV$14029) -> 0 | BJ6: =SUMIF($B$10:$B$1429,BI6,$BJ$10:$BJ$14029) -> 0 | BX6: =SUMIF($B$10:$B$1429,BW6,$BX$10:$BX$14029) -> 0 | CL6: =SUMIF($B$10:$B$1429,CK6,$CL$10:$CL$14029) -> 0 | CZ6: =SUMIF($B$10:$B$1429,CY6,$CZ$10:$CZ$14029) -> 0 | DN6: =SUMIF($B$10:$B$1429,DM6,$DN$10:$DN$14029) -> 0 | EB6: =SUMIF($B$10:$B$1429,EA6,$EB$10:$EB$14029) -> 0
D8: =SUBTOTAL(9,D10:D439) -> 569310 | G8: =SUBTOTAL(9,G10:G439) -> 0 | H8: =SUBTOTAL(9,H10:H439) -> 1333.3333 | I8: =SUBTOTAL(9,I10:I439) -> 1333.3333 | J8: =SUBTOTAL(9,J10:J439) -> 1333.3333 | K8: =SUBTOTAL(9,K10:K439) -> 1333.3333 | L8: =SUBTOTAL(9,L10:L439) -> 1333.3333 | M8: =SUBTOTAL(9,M10:M439) -> 1333.3333 | N8: =SUBTOTAL(9,N10:N439) -> 1333.3333 | ... EB8: =SUBTOTAL(9,EB10:EB439) -> 62383.333
A9: Date d'achat | B9: Classement | C9: Désignation | D9: Montant | E9: Durée | F9: Amortissement | G9: =EOMONTH($E$2,0) -> 41973 | H9: =EOMONTH(G9,1) -> 42004 | I9: =EOMONTH(H9,1) -> 42035 | J9: =EOMONTH(I9,1) -> 42063 | K9: =EOMONTH(J9,1) -> 42094 | L9: =EOMONTH(K9,1) -> 42124 | M9: =EOMONTH(L9,1) -> 42155 | N9: =EOMONTH(M9,1) -> 42185 | O9: =EOMONTH(N9,1) -> 42216 | ... R9: =EOMONTH(Q9,1) -> 42308 | S9: ="Amortissement"&" "&YEAR(E2)+1 -> Amortissement 2015 | T9: ="Valeur résiduelle"&" "&YEAR(E2)+1 -> Valeur résiduelle 2015 | U9: =EOMONTH(R9,1) -> 42338 | V9: =EOMONTH(U9,1) -> 42369 | W9: =EOMONTH(V9,1) -> 42400 | X9: =EOMONTH(W9,1) -> 42429 | Y9: =EOMONTH(X9,1) -> 42460 | Z9: =EOMONTH(Y9,1) -> 42490 | AA9: =EOMONTH(Z9,1) -> 42521 | AB9: =EOMONTH(AA9,1) -> 42551 | AC9: =EOMONTH(AB9,1) -> 42582 | ... AF9: =EOMONTH(AE9,1) -> 42674 | AG9: ="Amortissement"&" "&YEAR(E2)+2 -> Amortissement 2016 | AH9: ="Valeur résiduelle"&" "&YEAR(E2)+2 -> Valeur résiduelle 2016 | AI9: =EOMONTH(AF9,1) -> 42704 | AJ9: =EOMONTH(AI9,1) -> 42735 | AK9: =EOMONTH(AJ9,1) -> 42766 | AL9: =EOMONTH(AK9,1) -> 42794 | AM9: =EOMONTH(AL9,1) -> 42825 | AN9: =EOMONTH(AM9,1) -> 42855 | AO9: =EOMONTH(AN9,1) -> 42886 | AP9: =EOMONTH(AO9,1) -> 42916 | AQ9: =EOMONTH(AP9,1) -> 42947 | ... AT9: =EOMONTH(AS9,1) -> 43039 | AU9: ="Amortissement"&" "&YEAR(E2)+3 -> Amortissement 2017 | AV9: ="Valeur résiduelle"&" "&YEAR(E2)+3 -> Valeur résiduelle 2017 | AW9: =EOMONTH(AT9,1) -> 43069 | AX9: =EOMONTH(AW9,1) -> 43100 | AY9: =EOMONTH(AX9,1) -> 43131 | AZ9: =EOMONTH(AY9,1) -> 43159 | BA9: =EOMONTH(AZ9,1) -> 43190 | BB9: =EOMONTH(BA9,1) -> 43220 | BC9: =EOMONTH(BB9,1) -> 43251 | BD9: =EOMONTH(BC9,1) -> 43281 | BE9: =EOMONTH(BD9,1) -> 43312 | ... BH9: =EOMONTH(BG9,1) -> 43404 | BI9: ="Amortissement"&" "&YEAR(E2)+4 -> Amortissement 2018 | BJ9: ="Valeur résiduelle"&" "&YEAR(E2)+4 -> Valeur résiduelle 2018 | BK9: =EOMONTH(BH9,1) -> 43434 | BL9: =EOMONTH(BK9,1) -> 43465 | BM9: =EOMONTH(BL9,1) -> 43496 | BN9: =EOMONTH(BM9,1) -> 43524 | BO9: =EOMONTH(BN9,1) -> 43555 | BP9: =EOMONTH(BO9,1) -> 43585 | BQ9: =EOMONTH(BP9,1) -> 43616 | BR9: =EOMONTH(BQ9,1) -> 43646 | BS9: =EOMONTH(BR9,1) -> 43677 | ... BV9: =EOMONTH(BU9,1) -> 43769 | BW9: ="Amortissement"&" "&YEAR(E2)+5 -> Amortissement 2019 | BX9: ="Valeur résiduelle"&" "&YEAR(E2)+5 -> Valeur résiduelle 2019 | BY9: =EOMONTH(BV9,1) -> 43799 | BZ9: =EOMONTH(BY9,1) -> 43830 | CA9: =EOMONTH(BZ9,1) -> 43861 | CB9: =EOMONTH(CA9,1) -> 43890 | CC9: =EOMONTH(CB9,1) -> 43921 | CD9: =EOMONTH(CC9,1) -> 43951 | CE9: =EOMONTH(CD9,1) -> 43982 | CF9: =EOMONTH(CE9,1) -> 44012 | CG9: =EOMONTH(CF9,1) -> 44043 | ... CJ9: =EOMONTH(CI9,1) -> 44135 | CK9: ="Amortissement"&" "&YEAR(E2)+6 -> Amortissement 2020 | CL9: ="Valeur résiduelle"&" "&YEAR(E2)+6 -> Valeur résiduelle 2020 | CM9: =EOMONTH(CJ9,1) -> 44165 | CN9: =EOMONTH(CM9,1) -> 44196 | CO9: =EOMONTH(CN9,1) -> 44227 | CP9: =EOMONTH(CO9,1) -> 44255 | CQ9: =EOMONTH(CP9,1) -> 44286 | CR9: =EOMONTH(CQ9,1) -> 44316 | CS9: =EOMONTH(CR9,1) -> 44347 | CT9: =EOMONTH(CS9,1) -> 44377 | CU9: =EOMONTH(CT9,1) -> 44408 | ... CX9: =EOMONTH(CW9,1) -> 44500 | CY9: ="Amortissement"&" "&YEAR(E2)+7 -> Amortissement 2021 | CZ9: ="Valeur résiduelle"&" "&YEAR(E2)+7 -> Valeur résiduelle 2021 | DA9: =EOMONTH(CX9,1) -> 44530 | DB9: =EOMONTH(DA9,1) -> 44561 | DC9: =EOMONTH(DB9,1) -> 44592 | DD9: =EOMONTH(DC9,1) -> 44620 | DE9: =EOMONTH(DD9,1) -> 44651 | DF9: =EOMONTH(DE9,1) -> 44681 | DG9: =EOMONTH(DF9,1) -> 44712 | DH9: =EOMONTH(DG9,1) -> 44742 | DI9: =EOMONTH(DH9,1) -> 44773 | ... DL9: =EOMONTH(DK9,1) -> 44865 | DM9: ="Amortissement"&" "&YEAR(E2)+8 -> Amortissement 2022 | DN9: ="Valeur résiduelle"&" "&YEAR(E2)+8 -> Valeur résiduelle 2022 | DO9: =EOMONTH(DL9,1) -> 44895 | DP9: =EOMONTH(DO9,1) -> 44926 | DQ9: =EOMONTH(DP9,1) -> 44957 | DR9: =EOMONTH(DQ9,1) -> 44985 | DS9: =EOMONTH(DR9,1) -> 45016 | DT9: =EOMONTH(DS9,1) -> 45046 | DU9: =EOMONTH(DT9,1) -> 45077 | DV9: =EOMONTH(DU9,1) -> 45107 | DW9: =EOMONTH(DV9,1) -> 45138 | ... DZ9: =EOMONTH(DY9,1) -> 45230 | EA9: ="Amortissement"&" "&YEAR(E2)+9 -> Amortissement 2023 | EB9: ="Valeur résiduelle"&" "&YEAR(E2)+9 -> Valeur résiduelle 2023
A10: 41974 | B10: Aménagement | C10: Vitrine interieur magasin | D10: 80000 | E10: 5 | F10: =D10/E10 -> 16000 | G10: =IF(OR($F10<=0,(G$9-$A10)>(365*$E10)),0,IF($A10<=G$9,$F10/12,0)) -> 0 | H10: =IF(OR($F10<=0,(H$9-$A10)>(365*$E10)),0,IF($A10<=H$9,$F10/12,0)) -> 1333.3333 | I10: =IF(OR($F10<=0,(I$9-$A10)>(365*$E10)),0,IF($A10<=I$9,$F10/12,0)) -> 1333.3333 | J10: =IF(OR($F10<=0,(J$9-$A10)>(365*$E10)),0,IF($A10<=J$9,$F10/12,0)) -> 1333.3333 | K10: =IF(OR($F10<=0,(K$9-$A10)>(365*$E10)),0,IF($A10<=K$9,$F10/12,0)) -> 1333.3333 | L10: =IF(OR($F10<=0,(L$9-$A10)>(365*$E10)),0,IF($A10<=L$9,$F10/12,0)) -> 1333.3333 | M10: =IF(OR($F10<=0,(M$9-$A10)>(365*$E10)),0,IF($A10<=M$9,$F10/12,0)) -> 1333.3333 | N10: =IF(OR($F10<=0,(N$9-$A10)>(365*$E10)),0,IF($A10<=N$9,$F10/12,0)) -> 1333.3333 | ... R10: =IF(OR($F10<=0,(R$9-$A10)>(365*$E10)),0,IF($A10<=R$9,$F10/12,0)) -> 1333.3333 | S10: =SUM(G10:R10) -> 14666.667 | T10: =IF(AND($R$9>A10,$S10<>0),$D10-$S10,0) -> 65333.333 | U10: =IF(OR($F10<=0,(U$9-$A10)>(365*$E10)),0,IF($A10<=U$9,$F10/12,0)) -> 1333.3333 | V10: =IF(OR($F10<=0,(V$9-$A10)>(365*$E10)),0,IF($A10<=V$9,$F10/12,0)) -> 1333.3333 | W10: =IF(OR($F10<=0,(W$9-$A10)>(365*$E10)),0,IF($A10<=W$9,$F10/12,0)) -> 1333.3333 | X10: =IF(OR($F10<=0,(X$9-$A10)>(365*$E10)),0,IF($A10<=X$9,$F10/12,0)) -> 1333.3333 | Y10: =IF(OR($F10<=0,(Y$9-$A10)>(365*$E10)),0,IF($A10<=Y$9,$F10/12,0)) -> 1333.3333 | Z10: =IF(OR($F10<=0,(Z$9-$A10)>(365*$E10)),0,IF($A10<=Z$9,$F10/12,0)) -> 1333.3333 | AA10: =IF(OR($F10<=0,(AA$9-$A10)>(365*$E10)),0,IF($A10<=AA$9,$F10/12,0)) -> 1333.3333 | AB10: =IF(OR($F10<=0,(AB$9-$A10)>(365*$E10)),0,IF($A10<=AB$9,$F10/12,0)) -> 1333.3333 | ... AF10: =IF(OR($F10<=0,(AF$9-$A10)>(365*$E10)),0,IF($A10<=AF$9,$F10/12,0)) -> 1333.3333 | AG10: =SUM(U10:AF10) -> 16000 | AH10: =IF(AND($AF$9>$A10,$AG10<>0),$D10-$S10-$AG10,0) -> 49333.333 | AI10: =IF(OR($F10<=0,(AI$9-$A10)>(365*$E10)),0,IF($A10<=AI$9,$F10/12,0)) -> 1333.3333 | AJ10: =IF(OR($F10<=0,(AJ$9-$A10)>(365*$E10)),0,IF($A10<=AJ$9,$F10/12,0)) -> 1333.3333 | AK10: =IF(OR($F10<=0,(AK$9-$A10)>(365*$E10)),0,IF($A10<=AK$9,$F10/12,0)) -> 1333.3333 | AL10: =IF(OR($F10<=0,(AL$9-$A10)>(365*$E10)),0,IF($A10<=AL$9,$F10/12,0)) -> 1333.3333 | AM10: =IF(OR($F10<=0,(AM$9-$A10)>(365*$E10)),0,IF($A10<=AM$9,$F10/12,0)) -> 1333.3333 | AN10: =IF(OR($F10<=0,(AN$9-$A10)>(365*$E10)),0,IF($A10<=AN$9,$F10/12,0)) -> 1333.3333 | AO10: =IF(OR($F10<=0,(AO$9-$A10)>(365*$E10)),0,IF($A10<=AO$9,$F10/12,0)) -> 1333.3333 | AP10: =IF(OR($F10<=0,(AP$9-$A10)>(365*$E10)),0,IF($A10<=AP$9,$F10/12,0)) -> 1333.3333 | ... AT10: =IF(OR($F10<=0,(AT$9-$A10)>(365*$E10)),0,IF($A10<=AT$9,$F10/12,0)) -> 1333.3333 | AU10: =SUM(AI10:AT10) -> 16000 | AV10: =IF(AND($AT$9>$A10,$AU10<>0),$D10-$S10-$AG10-$AU10,0) -> 33333.333 | AW10: =IF(OR($F10<=0,(AW$9-$A10)>(365*$E10)),0,IF($A10<=AW$9,$F10/12,0)) -> 1333.3333 | AX10: =IF(OR($F10<=0,(AX$9-$A10)>(365*$E10)),0,IF($A10<=AX$9,$F10/12,0)) -> 1333.3333 | AY10: =IF(OR($F10<=0,(AY$9-$A10)>(365*$E10)),0,IF($A10<=AY$9,$F10/12,0)) -> 1333.3333 | AZ10: =IF(OR($F10<=0,(AZ$9-$A10)>(365*$E10)),0,IF($A10<=AZ$9,$F10/12,0)) -> 1333.3333 | BA10: =IF(OR($F10<=0,(BA$9-$A10)>(365*$E10)),0,IF($A10<=BA$9,$F10/12,0)) -> 1333.3333 | BB10: =IF(OR($F10<=0,(BB$9-$A10)>(365*$E10)),0,IF($A10<=BB$9,$F10/12,0)) -> 1333.3333 | BC10: =IF(OR($F10<=0,(BC$9-$A10)>(365*$E10)),0,IF($A10<=BC$9,$F10/12,0)) -> 1333.3333 | BD10: =IF(OR($F10<=0,(BD$9-$A10)>(365*$E10)),0,IF($A10<=BD$9,$F10/12,0)) -> 1333.3333 | ... BH10: =IF(OR($F10<=0,(BH$9-$A10)>(365*$E10)),0,IF($A10<=BH$9,$F10/12,0)) -> 1333.3333 | BI10: =SUM(AW10:BH10) -> 16000 | BJ10: =IF(AND($BH$9>$A10,$BI10<>0),$D10-$S10-$AG10-$AU10-$BI10,0) -> 17333.333 | BK10: =IF(OR($BJ10<=0,(BK$9-$A10)>($E10*365)),0,IF($A10<=BK$9,$F10/12)) -> 1333.3333 | BL10: =IF(OR($BJ10<=0,(BL$9-$A10)>($E10*365)),0,IF($A10<=BL$9,$F10/12)) -> 1333.3333 | BM10: =IF(OR($BJ10<=0,(BM$9-$A10)>($E10*365)),0,IF($A10<=BM$9,$F10/12)) -> 1333.3333 | BN10: =IF(OR($BJ10<=0,(BN$9-$A10)>($E10*365)),0,IF($A10<=BN$9,$F10/12)) -> 1333.3333 | BO10: =IF(OR($BJ10<=0,(BO$9-$A10)>($E10*365)),0,IF($A10<=BO$9,$F10/12)) -> 1333.3333 | BP10: =IF(OR($BJ10<=0,(BP$9-$A10)>($E10*365)),0,IF($A10<=BP$9,$F10/12)) -> 1333.3333 | BQ10: =IF(OR($BJ10<=0,(BQ$9-$A10)>($E10*365)),0,IF($A10<=BQ$9,$F10/12)) -> 1333.3333 | BR10: =IF(OR($BJ10<=0,(BR$9-$A10)>($E10*365)),0,IF($A10<=BR$9,$F10/12)) -> 1333.3333 | ... BV10: =IF(OR($BJ10<=0,(BV$9-$A10)>($E10*365)),0,IF($A10<=BV$9,$F10/12)) -> 1333.3333 | BW10: =SUM(BK10:BV10) -> 16000 | BX10: =IF(AND($BV$9>$A10,$BW10<>0),$D10-$S10-$AG10-$AU10-$BI10-$BW10,0) -> 1333.3333 | BY10: =IF(OR($BX10<=0,(BY$9-$A10)>($E10*365)),0,IF($A10<=BY$9,$F10/12)) -> 1333.3333 | BZ10: =IF(OR($BX10<=0,(BZ$9-$A10)>($E10*365)),0,IF($A10<=BZ$9,$F10/12)) -> 0 | CA10: =IF(OR($BX10<=0,(CA$9-$A10)>($E10*365)),0,IF($A10<=CA$9,$F10/12)) -> 0 | CB10: =IF(OR($BX10<=0,(CB$9-$A10)>($E10*365)),0,IF($A10<=CB$9,$F10/12)) -> 0 | CC10: =IF(OR($BX10<=0,(CC$9-$A10)>($E10*365)),0,IF($A10<=CC$9,$F10/12)) -> 0 | CD10: =IF(OR($BX10<=0,(CD$9-$A10)>($E10*365)),0,IF($A10<=CD$9,$F10/12)) -> 0 | CE10: =IF(OR($BX10<=0,(CE$9-$A10)>($E10*365)),0,IF($A10<=CE$9,$F10/12)) -> 0 | CF10: =IF(OR($BX10<=0,(CF$9-$A10)>($E10*365)),0,IF($A10<=CF$9,$F10/12)) -> 0 | ... CJ10: =IF(OR($BX10<=0,(CJ$9-$A10)>($E10*365)),0,IF($A10<=CJ$9,$F10/12)) -> 0 | CK10: =SUM(BY10:CJ10) -> 1333.3333 | CL10: =IF(AND($CJ$9>$A10,$CK10<>0),$D10-$S10-$AG10-$AU10-$BI10-$BW10-$CK$10,0) -> -6.5938366e-12 | CM10: =IF(OR($CL10<=0,(CM$9-$A10)>($E10*365)),0,IF($A10<=CM$9,$F10/12)) -> 0 | CN10: =IF(OR($CL10<=0,(CN$9-$A10)>($E10*365)),0,IF($A10<=CN$9,$F10/12)) -> 0 | CO10: =IF(OR($CL10<=0,(CO$9-$A10)>($E10*365)),0,IF($A10<=CO$9,$F10/12)) -> 0 | CP10: =IF(OR($CL10<=0,(CP$9-$A10)>($E10*365)),0,IF($A10<=CP$9,$F10/12)) -> 0 | CQ10: =IF(OR($CL10<=0,(CQ$9-$A10)>($E10*365)),0,IF($A10<=CQ$9,$F10/12)) -> 0 | CR10: =IF(OR($CL10<=0,(CR$9-$A10)>($E10*365)),0,IF($A10<=CR$9,$F10/12)) -> 0 | CS10: =IF(OR($CL10<=0,(CS$9-$A10)>($E10*365)),0,IF($A10<=CS$9,$F10/12)) -> 0 | CT10: =IF(OR($CL10<=0,(CT$9-$A10)>($E10*365)),0,IF($A10<=CT$9,$F10/12)) -> 0 | ... CX10: =IF(OR($CL10<=0,(CX$9-$A10)>($E10*365)),0,IF($A10<=CX$9,$F10/12)) -> 0 | CY10: =SUM(CM10:CX10) -> 0 | CZ10: =IF(AND($CX$9>$A10,$CY10<>0),$D10-$S10-$AG10-$AU10-$BI10-$BW10-$CK10-$CY10,0) -> 0 | DA10: =IF(OR($CZ10<=0,(DA$9-$A10)>($E10*365)),0,IF($A10<=DA$9,$F10/12)) -> 0 | DB10: =IF(OR($CZ10<=0,(DB$9-$A10)>($E10*365)),0,IF($A10<=DB$9,$F10/12)) -> 0 | DC10: =IF(OR($CZ10<=0,(DC$9-$A10)>($E10*365)),0,IF($A10<=DC$9,$F10/12)) -> 0 | DD10: =IF(OR($CZ10<=0,(DD$9-$A10)>($E10*365)),0,IF($A10<=DD$9,$F10/12)) -> 0 | DE10: =IF(OR($CZ10<=0,(DE$9-$A10)>($E10*365)),0,IF($A10<=DE$9,$F10/12)) -> 0 | DF10: =IF(OR($CZ10<=0,(DF$9-$A10)>($E10*365)),0,IF($A10<=DF$9,$F10/12)) -> 0 | DG10: =IF(OR($CZ10<=0,(DG$9-$A10)>($E10*365)),0,IF($A10<=DG$9,$F10/12)) -> 0 | DH10: =IF(OR($CZ10<=0,(DH$9-$A10)>($E10*365)),0,IF($A10<=DH$9,$F10/12)) -> 0 | ... DL10: =IF(OR($CZ10<=0,(DL$9-$A10)>($E10*365)),0,IF($A10<=DL$9,$F10/12)) -> 0 | DM10: =SUM(DA10:DL10) -> 0 | DN10: =IF(AND($DL$9>$A10,$DM10<>0),$D10-$S10-$AG10-$AU10-$BI10-$BW10-$CK$10-$CY10-$DM10,0) -> 0 | DO10: =IF(OR($DN10<=0,(DO$9-$A10)>($E10*365)),0,IF($A10<=DO$9,$F10/12)) -> 0 | DP10: =IF(OR($DN10<=0,(DP$9-$A10)>($E10*365)),0,IF($A10<=DP$9,$F10/12)) -> 0 | DQ10: =IF(OR($DN10<=0,(DQ$9-$A10)>($E10*365)),0,IF($A10<=DQ$9,$F10/12)) -> 0 | DR10: =IF(OR($DN10<=0,(DR$9-$A10)>($E10*365)),0,IF($A10<=DR$9,$F10/12)) -> 0 | DS10: =IF(OR($DN10<=0,(DS$9-$A10)>($E10*365)),0,IF($A10<=DS$9,$F10/12)) -> 0 | DT10: =IF(OR($DN10<=0,(DT$9-$A10)>($E10*365)),0,IF($A10<=DT$9,$F10/12)) -> 0 | DU10: =IF(OR($DN10<=0,(DU$9-$A10)>($E10*365)),0,IF($A10<=DU$9,$F10/12)) -> 0 | DV10: =IF(OR($DN10<=0,(DV$9-$A10)>($E10*365)),0,IF($A10<=DV$9,$F10/12)) -> 0 | ... DZ10: =IF(OR($DN10<=0,(DZ$9-$A10)>($E10*365)),0,IF($A10<=DZ$9,$F10/12)) -> 0 | EA10: =SUM(DO10:DZ10) -> 0 | EB10: =IF(AND($DZ$9>$A10,$EA10<>0),$D10-$S10-$AG10-$AU10-$BI10-$BW10--CY10-$DM10-$CK10-$EA10,0) -> 0
